Workbook
Name pic: INDEX(納入・納付申告書!A1:D2,1,0)
Name 特徴者: [1]特徴者!$B$2:$B$42
Name 特徴者一覧: #REF!

Sheet 基本データ
B1: 熊本県産業廃棄物税申告書作成支援シート | D1: 元号 | E1: 令和 | G1: 今日 | H1: =TODAY() -> 46168 | I1: =YEAR(H1)-E2 -> 8 | J1: =MONTH(H1) -> 5 | K1: =DAY(H1) -> 26 | L1: 和暦作成 | M1: =E1&I1&"年"&J1&"月"&K1&"日" -> 令和8年5月26日
D2: 元年の前年の西暦→ | E2: 2018
A3: 以下のデータが各申告書等へ連動します。
B4: 所管振興局名 | C4: 県央広域本部 | G4: 県央広域本部
C5: =HLOOKUP(C4,G4:Q5,2,0) -> 43001 | G5: 43001
B6: 熊本県納番 | C6: 2019
B7: 枝番号 | C7: 2020 | H7: ="第"&C6&"号（熊本県納番）" -> 第2019号（熊本県納番）
K9: =IF(L9=#REF!,1,"") -> #REF! | L9: する | M9: しない
P14: =納入・納付申告書!W43 -> 7 | Q14: =MONTH(納入・納付申告書!CA45) -> 6 | S14: 申告期限 | T14: =VLOOKUP(Q14,Q18:V29,6,0) -> 34911 | U14: (aaa) | V14: =YEAR(T14)-1988 -> 7 | W14: =MONTH(T14) -> 7 | X14: =DAY(T14) -> 31
S15: 申告期限和暦合成 | T15: =DBCS(E1&YEAR(T14)-E2&"年"&MONTH(T14)&"月"&DAY(T14)&"日"&TEXT(T14,U14)) -> 令和－２３年７月３１日（月） | U15: =YEAR(T14)-$E$2 -> -23 | V15: =MONTH(T14) -> 7 | W15: =DAY(T14) -> 31
Q16: 申告期限算定表
N17: 基準期間 | Q17: 実績月 | R17: 通常の期限 | T17: 日付合成 | U17: 曜日判定 | V17: 申告期限
N18: =納入・納付申告書!CA45 -> 45809 | O18: =DATE(YEAR(N18),MONTH(N18)+1,1)-1 -> 45838 | Q18: 12 | R18: 1 | S18: 31 | T18: =DATE(P14+1989,R18,S18) -> 35095 | U18: =WEEKDAY(T18) -> 4 | V18: =IF(U18=7,T18+2,IF(U18=1,T18+1,T18)) -> 35095
O19: m"月"d"日" | Q19: 1 | R19: 2 | S19: =DAY(DATE(P14+1988+1988,3,1)-1) -> 28 | T19: =DATE(P14+1988,R19,S19) -> 34758 | U19: =WEEKDAY(T19) -> 3 | V19: =IF(U19=7,T19+2,IF(U19=1,T19+1,T19)) -> 34758
O20: e"年"m"月"d"日" | Q20: 2 | R20: 3 | S20: 31 | T20: =DATE(P14+1988,R20,S20) -> 34789 | U20: =WEEKDAY(T20) -> 6 | V20: =IF(U20=7,T20+2,IF(U20=1,T20+1,T20)) -> 34789
Q21: 3 | R21: 4 | S21: 30 | T21: =DATE(P14+1988,R21,S21) -> 34819 | U21: =WEEKDAY(T21) -> 1 | V21: =IF(U21=7,T21+2,IF(OR(U21=1,U21=2),T21+1,T21)) -> 34820
Q22: 4 | R22: 5 | S22: 31 | T22: =DATE(P14+1988,R22,S22) -> 34850 | U22: =WEEKDAY(T22) -> 4 | V22: =IF(U22=7,T22+2,IF(U22=1,T22+1,T22)) -> 34850
Q23: 5 | R23: 6 | S23: 30 | T23: =DATE(P14+1988,R23,S23) -> 34880 | U23: =WEEKDAY(T23) -> 6 | V23: =IF(U23=7,T23+2,IF(U23=1,T23+1,T23)) -> 34880
Q24: 6 | R24: 7 | S24: 31 | T24: =DATE(P14+1988,R24,S24) -> 34911 | U24: =WEEKDAY(T24) -> 2 | V24: =IF(U24=7,T24+2,IF(U24=1,T24+1,T24)) -> 34911
Q25: 7 | R25: 8 | S25: 31 | T25: =DATE(P14+1988,R25,S25) -> 34942 | U25: =WEEKDAY(T25) -> 5 | V25: =IF(U25=7,T25+2,IF(U25=1,T25+1,T25)) -> 34942
Q26: 8 | R26: 9 | S26: 30 | T26: =DATE(P14+1988,R26,S26) -> 34972 | U26: =WEEKDAY(T26) -> 7 | V26: =IF(U26=7,T26+2,IF(U26=1,T26+1,T26)) -> 34974
Q27: 9 | R27: 10 | S27: 31 | T27: =DATE(P14+1988,R27,S27) -> 35003 | U27: =WEEKDAY(T27) -> 3 | V27: =IF(U27=7,T27+2,IF(U27=1,T27+1,T27)) -> 35003
Q28: 10 | R28: 11 | S28: 30 | T28: =DATE(P14+1988,R28,S28) -> 35033 | U28: =WEEKDAY(T28) -> 5 | V28: =IF(U28=7,T28+2,IF(U28=1,T28+1,T28)) -> 35033
Q29: 11 | R29: 1 | S29: 4 | T29: =DATE(P14+1989,R29,S29) -> 35068 | U29: =WEEKDAY(T29) -> 5 | V29: =IF(U29=7,T29+2,IF(U29=1,T29+1,T29)) -> 35068

Sheet 納入・納付申告書
CD4: （管理型） | CE4: （安定型）
E5: 受 付 印 | AC5: ※ 納税者番号 | AT5: =基本データ!C6 -> 2019 | BK5: ◆ | BN5: =基本データ!C7 -> 2020
Y6: 住所又は所在地 | AV6: 熊本市北区楠野町１０４６－２
S7: 特別徴収義務者 | U7: 又は納税者
Y12: 氏名又は名称 | AV12: 有限会社 オー・エス収集センター | BS12: 印
AV14: 代表取締役 野原 雅浩
Y15: 個人番号又は 法人番号 （右詰で記載） | AV15: 6 | AX15: 3 | AZ15: 3 | BB15: 0 | BD15: 0 | BF15: 0 | BH15: 2 | BJ15: 0 | BL15: 0 | BN15: 1 | BP15: 6 | BR15: 3 | BT15: 5
Y17: 担当部課名 | AV17: 松田 英樹
C18: =基本データ!M1 -> 令和8年5月26日
Y20: 及び担当者氏名 | AZ20: （電話 ０９６ - ２４５ - ０１１０ ）
S22: 最終処分場
C23: ="熊本県"&基本データ!C4&"長" -> 熊本県県央広域本部長 | Q23: 様 | Y23: 所在地 | AV23: 熊本市北区明徳町字上市迫1番地外
Y28: 名称 （処分場種類） | AV28: 有限会社 オー・エス収集センター
AV29: （管理型）
B32: 産業廃棄物税 | AJ32: 納 入 | AU32: 申告書
AJ34: 納 付
C38: 福岡県産業廃棄物税条例第10条第７項の規定により、下記のとおり登録事項の変更を申請します。 | D38: 熊本県産業廃棄物税条例 | T38: 第１１条第１項(第２項) | AW38: の規定により、次のとおり申告します。
T39: 第１４条第１項
C41: 申告区分 | Q41: 納入申告 ・ 納付申告 | CA41: =基本データ!E1 -> 令和
CA42: 申告月計算
C43: 実績月 | R43: =基本データ!E1 -> 令和 | W43: 7 | AA43: 年 | AD43: 4 | AH43: 月分から | AR43: =CB45&"分まで" -> 令和7年6月分まで | CA43: =DATE(基本データ!E2+W43,AD43,1) -> 45748 | CB43: =$CA$41&$W$43&"年"&MONTH(CA43)&"月" -> 令和7年4月 | CF43: =IF(AD43=12,W43+1,W43) -> 7 | CJ43: 年 | CM43: =IF(AD43=1,4,IF(AD43=4,7,IF(AD43=7,10,1))) -> 7
CA44: =DATE(YEAR(CA43),MONTH(CA43)+1,1) -> 45778 | CB44: =$CA$41&$W$43&"年"&MONTH(CA44)&"月" -> 令和7年5月
C45: 特別徴収に係る産業廃棄物の搬入重量 | AY45: ① | BA45: =附表１!O25 -> 0 | CA45: =DATE(YEAR(CA44),MONTH(CA44)+1,1) -> 45809 | CB45: =$CA$41&$W$43&"年"&MONTH(CA45)&"月" -> 令和7年6月
C47: 申告納付に係る産業廃棄物の搬入重量 | AY47: ② | BA47: =附表１!AJ25 -> 0
C49: この申告により納入すべき産業廃棄物税額（①×1,000円／ﾄﾝ） | BA49: =BA45*1000 -> 0
C51: この申告により納付すべき産業廃棄物税額（②×1,000円／ﾄﾝ） | BA51: =BA47*1000 -> 0
C53: 申告期限 | Q53: 45869
C55: 備考
B58: (注) | E58: １ 「申告区分」欄は、該当する項目に○をつけてください。
E59: ２ 附表１（課税標準に関する明細書（その１））及び附表２（課税標準に関する明細書（その
E60: ２））を添付してください。
E61: ３ ※印の欄には、記入しないでください。

Sheet 附表１
AD3: 特別徴収義務者(納税者)名 | BA3: =納入・納付申告書!AV12 -> 有限会社 オー・エス収集センター
B5: 課税標準に関する明細書（その１）
B6: 実績月 | S6: =納入・納付申告書!CB43&"分から"&納入・納付申告書!CB45&"分まで" -> 令和7年4月分から令和7年6月分まで | CM6: ggge"年"m"月分"
B7: 区 分
O8: 委託処理 | AJ8: 自己処理 | BE8: 合計重量 | CM8: m"月分"
O9: に係る搬入重量 | AJ9: に係る搬入重量
O10: (ア) | AJ10: (イ) | BE10: (ア)＋(イ)
B12: 課 税 標 準 と な る 搬 入
C13: =TEXT(納入・納付申告書!CA43,$CM$8) -> 4月分 | O13: =委附表2!AS29 -> 0 | AJ13: =自附表2!AS29 -> 0 | BE13: =O13+AJ13 -> 0
C17: =TEXT(納入・納付申告書!CA44,$CM$8) -> 5月分 | O17: =委附表2!AS60 -> 0 | AJ17: =自附表2!AS60 -> 0 | BE17: =O17+AJ17 -> 0
C21: =TEXT(納入・納付申告書!CA45,$CM$8) -> 6月分 | O21: =委附表2!AS91 -> 0 | AJ21: =自附表2!AS91 -> 0 | BE21: =O21+AJ21 -> 0
C25: 合 計 | O25: =SUM(O13,O17,O21) -> 0 | AJ25: =SUM(AJ13,AJ17,AJ21) -> 0 | BE25: =SUM(BE13,BE17,BE21) -> 0
C29: 備 考

Sheet 委附表2
X3: 特別徴収義務者(納税者)名 | AN3: =納入・納付申告書!$AV$12 -> 有限会社 オー・エス収集センター
B5: 課税標準に関する明細書(その２）
B6: 実績月 | K6: =納入・納付申告書!CB43&"分" -> 令和7年4月分 | AE6: 処理区分 | AM6: 委託処理 ・ 自己処理 | BV6: ggge"年"m"月分"
B8: 産業廃棄物の種類 | O8: 搬入重量（トン） | Y8: 重量の測定が困難な場合 | AS8: 合計（トン）
Y9: 体積（） | AE9: 換算係数 | AI9: 換算重量（トン）
O10: (ア) | Y10: (Ａ) | AE10: (Ｂ) | AI10: (A)×(B)=(イ) | AS10: (ア)+(イ)
C11: 燃え殻 | AE11: =1.14*1 -> 1.14 | AI11: =ROUNDDOWN(ROUNDDOWN(Y11,3)*AE11,5) -> 0 | AS11: =O11+AI11 -> 0
C12: 汚泥 | AE12: =1.1*1 -> 1.1 | AI12: =ROUNDDOWN(ROUNDDOWN(Y12,3)*AE12,5) -> 0 | AS12: =O12+AI12 -> 0
C13: 廃油 | AE13: =0.9*1 -> 0.9 | AI13: =ROUNDDOWN(ROUNDDOWN(Y13,3)*AE13,5) -> 0 | AS13: =O13+AI13 -> 0
C14: 廃プラスチック類 | AE14: =0.35*1 -> 0.35 | AI14: =ROUNDDOWN(ROUNDDOWN(Y14,3)*AE14,5) -> 0 | AS14: =O14+AI14 -> 0
C15: 紙くず | AE15: =0.3*1 -> 0.3 | AI15: =ROUNDDOWN(ROUNDDOWN(Y15,3)*AE15,5) -> 0 | AS15: =O15+AI15 -> 0
C16: 木くず | AE16: =0.55*1 -> 0.55 | AI16: =ROUNDDOWN(ROUNDDOWN(Y16,3)*AE16,5) -> 0 | AS16: =O16+AI16 -> 0
C17: 繊維くず | AE17: =0.12*1 -> 0.12 | AI17: =ROUNDDOWN(ROUNDDOWN(Y17,3)*AE17,5) -> 0 | AS17: =O17+AI17 -> 0
C18: 動物又は植物に係る 固形状の不要物 | AE18: =1*1 -> 1 | AI18: =ROUNDDOWN(ROUNDDOWN(Y18,3)*AE18,5) -> 0 | AS18: =O18+AI18 -> 0
C19: 獣畜及び食鳥に係る 固形状の不要物 | AE19: =1*1 -> 1 | AI19: =ROUNDDOWN(ROUNDDOWN(Y19,3)*AE19,5) -> 0 | AS19: =O19+AI19 -> 0
C20: ゴムくず | AE20: =1*0.52 -> 0.52 | AI20: =ROUNDDOWN(ROUNDDOWN(Y20,3)*AE20,5) -> 0 | AS20: =O20+AI20 -> 0
C21: 金属くず | AE21: =1*1.13 -> 1.13 | AI21: =ROUNDDOWN(ROUNDDOWN(Y21,3)*AE21,5) -> 0 | AS21: =O21+AI21 -> 0
C22: ガラスくず、コンクリートくず及び陶磁器くず | AE22: =1*1 -> 1 | AI22: =ROUNDDOWN(ROUNDDOWN(Y22,3)*AE22,5) -> 0 | AS22: =O22+AI22 -> 0
C23: 鉱さい | AE23: =1*1.93 -> 1.93 | AI23: =ROUNDDOWN(ROUNDDOWN(Y23,3)*AE23,5) -> 0 | AS23: =O23+AI23 -> 0
C24: コンクリートの破片その他これに類する不要物 | AE24: =1*1.48 -> 1.48 | AI24: =ROUNDDOWN(ROUNDDOWN(Y24,3)*AE24,5) -> 0 | AS24: =O24+AI24 -> 0
C25: 動物のふん尿 | AE25: =1*1 -> 1 | AI25: =ROUNDDOWN(ROUNDDOWN(Y25,3)*AE25,5) -> 0 | AS25: =O25+AI25 -> 0
C26: 動物の死体 | AE26: =1*1 -> 1 | AI26: =ROUNDDOWN(ROUNDDOWN(Y26,3)*AE26,5) -> 0 | AS26: =O26+AI26 -> 0
C27: ばいじん | AE27: =1*1.26 -> 1.26 | AI27: =ROUNDDOWN(ROUNDDOWN(Y27,3)*AE27,5) -> 0 | AS27: =O27+AI27 -> 0
C28: 廃棄物の処理及び清掃 に関する法律施行令 第2条第13号に掲げる 産業廃棄物 | AE28: =1*1 -> 1 | AI28: =ROUNDDOWN(ROUNDDOWN(Y28,3)*AE28,5) -> 0 | AS28: =O28+AI28 -> 0
C29: 合 計 | O29: =SUM(O11:X28) -> 0 | AI29: =SUM(AI11:AR28) -> 0 | AS29: =SUM(AS11:BB28) -> 0
B31: （注） | E31: １ この明細書は、月ごと及び処理区分ごとに作成してください。
E32: ２ 「処理区分」欄は、該当する項目に○をつけてください。
X34: 特別徴収義務者(納税者)名 | AN34: =納入・納付申告書!$AV$12 -> 有限会社 オー・エス収集センター
B36: 課税標準に関する明細書(その２）
B37: 実績月 | K37: =納入・納付申告書!CB44&"分" -> 令和7年5月分 | AE37: 処理区分 | AM37: 委託処理 ・ 自己処理 | BV37: ggge"年"m"月分"
B39: 産業廃棄物の種類 | O39: 搬入重量（トン） | Y39: 重量の測定が困難な場合 | AS39: 合計（トン）
Y40: 体積（） | AE40: 換算係数 | AI40: 換算重量（トン）
O41: (ア) | Y41: (Ａ) | AE41: (Ｂ) | AI41: (A)×(B)=(イ) | AS41: (ア)+(イ)
C42: 燃え殻 | AE42: =1.14*1 -> 1.14 | AI42: =ROUNDDOWN(ROUNDDOWN(Y42,3)*AE42,5) -> 0 | AS42: =O42+AI42 -> 0
C43: 汚泥 | AE43: =1.1*1 -> 1.1 | AI43: =ROUNDDOWN(ROUNDDOWN(Y43,3)*AE43,5) -> 0 | AS43: =O43+AI43 -> 0
C44: 廃油 | AE44: =0.9*1 -> 0.9 | AI44: =ROUNDDOWN(ROUNDDOWN(Y44,3)*AE44,5) -> 0 | AS44: =O44+AI44 -> 0
C45: 廃プラスチック類 | AE45: =0.35*1 -> 0.35 | AI45: =ROUNDDOWN(ROUNDDOWN(Y45,3)*AE45,5) -> 0 | AS45: =O45+AI45 -> 0
C46: 紙くず | AE46: =0.3*1 -> 0.3 | AI46: =ROUNDDOWN(ROUNDDOWN(Y46,3)*AE46,5) -> 0 | AS46: =O46+AI46 -> 0
C47: 木くず | AE47: =0.55*1 -> 0.55 | AI47: =ROUNDDOWN(ROUNDDOWN(Y47,3)*AE47,5) -> 0 | AS47: =O47+AI47 -> 0
C48: 繊維くず | AE48: =0.12*1 -> 0.12 | AI48: =ROUNDDOWN(ROUNDDOWN(Y48,3)*AE48,5) -> 0 | AS48: =O48+AI48 -> 0
...

Sheet 自附表2
X3: 特別徴収義務者(納税者)名 | AN3: =納入・納付申告書!$AV$12 -> 有限会社 オー・エス収集センター
B5: 課税標準に関する明細書(その２）
B6: 実績月 | K6: =納入・納付申告書!CB43&"分" -> 令和7年4月分 | AE6: 処理区分 | AM6: 委託処理 ・ 自己処理 | BV6: ggge"年"m"月分"
B8: 産業廃棄物の種類 | O8: 搬入重量（トン） | Y8: 重量の測定が困難な場合 | AS8: 合計（トン）
Y9: 体積（） | AE9: 換算係数 | AI9: 換算重量（トン）
O10: (ア) | Y10: (Ａ) | AE10: (Ｂ) | AI10: (A)×(B)=(イ) | AS10: (ア)+(イ)
C11: 燃え殻 | AE11: =委附表2!AE11 -> 1.14 | AI11: =ROUNDDOWN(ROUNDDOWN(Y11,3)*AE11,5) -> 0 | AS11: =O11+AI11 -> 0
C12: 汚泥 | AE12: =委附表2!AE12 -> 1.1 | AI12: =ROUNDDOWN(ROUNDDOWN(Y12,3)*AE12,5) -> 0 | AS12: =O12+AI12 -> 0
C13: 廃油 | AE13: =委附表2!AE13 -> 0.9 | AI13: =ROUNDDOWN(ROUNDDOWN(Y13,3)*AE13,5) -> 0 | AS13: =O13+AI13 -> 0
C14: 廃プラスチック類 | AE14: =委附表2!AE14 -> 0.35 | AI14: =ROUNDDOWN(ROUNDDOWN(Y14,3)*AE14,5) -> 0 | AS14: =O14+AI14 -> 0
C15: 紙くず | AE15: =委附表2!AE15 -> 0.3 | AI15: =ROUNDDOWN(ROUNDDOWN(Y15,3)*AE15,5) -> 0 | AS15: =O15+AI15 -> 0
C16: 木くず | AE16: =委附表2!AE16 -> 0.55 | AI16: =ROUNDDOWN(ROUNDDOWN(Y16,3)*AE16,5) -> 0 | AS16: =O16+AI16 -> 0
C17: 繊維くず | AE17: =委附表2!AE17 -> 0.12 | AI17: =ROUNDDOWN(ROUNDDOWN(Y17,3)*AE17,5) -> 0 | AS17: =O17+AI17 -> 0
C18: 動物又は植物に係る 固形状の不要物 | AE18: =委附表2!AE18 -> 1 | AI18: =ROUNDDOWN(ROUNDDOWN(Y18,3)*AE18,5) -> 0 | AS18: =O18+AI18 -> 0
C19: 獣畜及び食鳥に係る 固形状の不要物 | AE19: =委附表2!AE19 -> 1 | AI19: =ROUNDDOWN(ROUNDDOWN(Y19,3)*AE19,5) -> 0 | AS19: =O19+AI19 -> 0
C20: ゴムくず | AE20: =委附表2!AE20 -> 0.52 | AI20: =ROUNDDOWN(ROUNDDOWN(Y20,3)*AE20,5) -> 0 | AS20: =O20+AI20 -> 0
C21: 金属くず | AE21: =委附表2!AE21 -> 1.13 | AI21: =ROUNDDOWN(ROUNDDOWN(Y21,3)*AE21,5) -> 0 | AS21: =O21+AI21 -> 0
C22: ガラスくず、コンクリートくず及び陶磁器くず | AE22: =委附表2!AE22 -> 1 | AI22: =ROUNDDOWN(ROUNDDOWN(Y22,3)*AE22,5) -> 0 | AS22: =O22+AI22 -> 0
... C28: 廃棄物の処理及び清掃 に関する法律施行令 第2条第13号に掲げる 産業廃棄物 | AE28: =委附表2!AE28 -> 1 | AI28: =ROUNDDOWN(ROUNDDOWN(Y28,3)*AE28,5) -> 0 | AS28: =O28+AI28 -> 0
C29: 合 計 | O29: =SUM(O11:X28) -> 0 | Y29: =SUM(Y11:AD28) -> 0 | AI29: =SUM(AI11:AR28) -> 0 | AS29: =SUM(AS11:BB28) -> 0
B31: （注） | E31: １ この明細書は、月ごと及び処理区分ごとに作成してください。
E32: ２ 「処理区分」欄は、該当する項目に○をつけてください。
X34: 特別徴収義務者(納税者)名 | AN34: =納入・納付申告書!$AV$12 -> 有限会社 オー・エス収集センター
B36: 課税標準に関する明細書(その２）
B37: 実績月 | K37: =納入・納付申告書!CB44&"分" -> 令和7年5月分 | AE37: 処理区分 | AM37: 委託処理 ・ 自己処理 | BV37: ggge"年"m"月分"
B39: 産業廃棄物の種類 | O39: 搬入重量（トン） | Y39: 重量の測定が困難な場合 | AS39: 合計（トン）
Y40: 体積（） | AE40: 換算係数 | AI40: 換算重量（トン）
O41: (ア) | Y41: (Ａ) | AE41: (Ｂ) | AI41: (A)×(B)=(イ) | AS41: (ア)+(イ)
C42: 燃え殻 | AE42: =委附表2!AE42 -> 1.14 | AI42: =ROUNDDOWN(ROUNDDOWN(Y42,3)*AE42,5) -> 0 | AS42: =O42+AI42 -> 0
C43: 汚泥 | AE43: =委附表2!AE43 -> 1.1 | AI43: =ROUNDDOWN(ROUNDDOWN(Y43,3)*AE43,5) -> 0 | AS43: =O43+AI43 -> 0
C44: 廃油 | AE44: =委附表2!AE44 -> 0.9 | AI44: =ROUNDDOWN(ROUNDDOWN(Y44,3)*AE44,5) -> 0 | AS44: =O44+AI44 -> 0
C45: 廃プラスチック類 | AE45: =委附表2!AE45 -> 0.35 | AI45: =ROUNDDOWN(ROUNDDOWN(Y45,3)*AE45,5) -> 0 | AS45: =O45+AI45 -> 0
C46: 紙くず | AE46: =委附表2!AE46 -> 0.3 | AI46: =ROUNDDOWN(ROUNDDOWN(Y46,3)*AE46,5) -> 0 | AS46: =O46+AI46 -> 0
C47: 木くず | AE47: =委附表2!AE47 -> 0.55 | AI47: =ROUNDDOWN(ROUNDDOWN(Y47,3)*AE47,5) -> 0 | AS47: =O47+AI47 -> 0
C48: 繊維くず | AE48: =委附表2!AE48 -> 0.12 | AI48: =ROUNDDOWN(ROUNDDOWN(Y48,3)*AE48,5) -> 0 | AS48: =O48+AI48 -> 0
C49: 動物又は植物に係る 固形状の不要物 | AE49: =委附表2!AE49 -> 1 | AI49: =ROUNDDOWN(ROUNDDOWN(Y49,3)*AE49,5) -> 0 | AS49: =O49+AI49 -> 0
C50: 獣畜及び食鳥に係る 固形状の不要物 | AE50: =委附表2!AE50 -> 1 | AI50: =ROUNDDOWN(ROUNDDOWN(Y50,3)*AE50,5) -> 0 | AS50: =O50+AI50 -> 0
C51: ゴムくず | AE51: =委附表2!AE51 -> 0.52 | AI51: =ROUNDDOWN(ROUNDDOWN(Y51,3)*AE51,5) -> 0 | AS51: =O51+AI51 -> 0
C52: 金属くず | AE52: =委附表2!AE52 -> 1.13 | AI52: =ROUNDDOWN(ROUNDDOWN(Y52,3)*AE52,5) -> 0 | AS52: =O52+AI52 -> 0
C53: ガラスくず、コンクリートくず及び陶磁器くず | AE53: =委附表2!AE53 -> 1 | AI53: =ROUNDDOWN(ROUNDDOWN(Y53,3)*AE53,5) -> 0 | AS53: =O53+AI53 -> 0
...
